Workbook

Sheet Cover & Instructions
B2: TIRAP PERFORMANCE INDEX (TPI)
B6: Monthly Dashboard for All Departments | Office of the Deputy Commissioner, Tirap District
B9: HOW THIS DASHBOARD WORKS
B11: CADENCE: Monthly. All HoDs review together on the FIRST MONDAY of every month, 10:00 AM, DC Conference Room.
B13: DATA ENTRY: HoDs enter their numbers in their KRA tab by the 1st of each month, 12:00 noon. The 'Dashboard' tab
B14: auto-calculates achievement, status, and trends. No printing. No PowerPoint. The dashboard IS the meeting.
B16: STATUS COLOURS:
B17: GREEN = ≥90% of target achieved
B18: YELLOW = 70-89% achieved (warning, no action plan required yet)
B19: RED = <70% achieved (mandatory action plan in 'Action Tracker' tab within 7 days)
B21: REVIEW SEQUENCE (90 minutes total):
B22: 0-15 min: DC opens with last month's TPI score and one observation (good or bad).
... B68: measured doesn't exist. This dashboard is the single source of truth.

Sheet Dashboard
A1: TIRAP PERFORMANCE INDEX — MASTER DASHBOARD
A2: Reporting Month → | C2: Apr | D2: ← Select month from dropdown to update entire dashboard
A4: TPI SCORE | D4: GREEN | E4: YELLOW | F4: RED | G4: TOTAL INDICATORS
A5: =ROUND(J24,1) -> 19.6 | D5: =SUM(F10:F23) -> 18 | E5: =SUM(G10:G23) -> 0 | F5: =SUM(H10:H23) -> 106 | G5: 124
A8: KEY RESULT AREAS — ACHIEVEMENT BY DEPARTMENT
A9: # | B9: KRA | C9: Owner | D9: Weight | E9: Indicators | F9: Green | G9: Yellow | H9: Red | I9: Avg Achievement % | J9: KRA Score (0-100) | K9: Status | L9: Trend (3-mo) | M9: Top RED Indicator | N9: Action Status
A10: 1 | B10: H – Health Service Delivery | C10: DMO (District Medical Officer) | D10: 12 | E10: 12 | F10: =COUNTIF('KRA H - Health Service Deliver'!$V$5:$V$16,"GREEN") -> 3 | G10: =COUNTIF('KRA H - Health Service Deliver'!$V$5:$V$16,"YELLOW") -> 0 | H10: =COUNTIF('KRA H - Health Service Deliver'!$V$5:$V$16,"RED") -> 9 | I10: =IFERROR(AVERAGEIF('KRA H - Health Service Deliver'!$U$5:$U$16,">=0"),0) -> 0.29166667 | J10: =IFERROR(MIN(100,AVERAGEIF('KRA H - Health Service Deliver'!$U$5:$U$16,">=0")*100),0) -> 29.166667 | K10: =IF(J10>=90,"GREEN",IF(J10>=70,"YELLOW","RED")) -> RED | L10: =IFERROR(IF(OR(INDEX(Trends!$C$5:$N$5,MATCH($C$2,{"Apr","May","Jun","Jul","Aug","Sep","Oct","Nov","Dec","Jan","Feb","Mar"},0))="",IF(MATCH($C$2,{"Apr","May","Jun","Jul","Aug","Sep","Oct","Nov","Dec","Jan","Feb","Mar"},0)<=1,INDEX(Trends!$C$5:$N$5,MATCH($C$2,{"Apr","May","Jun","Jul","Aug","Sep","Oct","Nov","Dec","Jan","Feb","Mar"},0)),INDEX(Trends!$C$5:$N$5,MATCH($C$2,{"Apr","May","Jun","Jul","Aug","Sep","Oct","Nov","Dec","Jan","Feb","Mar"},0)-1))=""),"–",IF(INDEX(Trends!$C$5:$N$5,MATCH($C$2,{"Apr","May","Jun","Jul","Aug","Sep","Oct","Nov","Dec","Jan","Feb","Mar"},0))>IF(MATCH($C$2,{"Apr","May","Jun","Jul","Aug","Sep","Oct","Nov","Dec","Jan","Feb","Mar"},0)<=1,INDEX(Trends!$C$5:$N$5,MATCH($C$2,{"Apr","May","Jun","Jul","Aug","Sep","Oct","Nov","Dec","Jan","Feb","Mar"},0)),INDEX(Trends!$C$5:$N$5,MATCH($C$2,{"Apr","May","Jun","Jul","Aug","Sep","Oct","Nov","Dec","Jan","Feb","Mar"},0)-1))+2,"↑ up",IF(INDEX(Trends!$C$5:$N$5,MATCH($C$2,{"Apr","May","Jun","Jul","Aug","Sep","Oct","Nov","Dec","Jan","Feb","Mar"},0))<IF(MATCH($C$2,{"Apr","May","Jun","Jul","Aug","Sep","Oct","Nov","Dec","Jan","Feb","Mar"},0)<=1,INDEX(Trends!$C$5:$N$5,MATCH($C$2,{"Apr","May","Jun","Jul","Aug","Sep","Oct","Nov","Dec","Jan","Feb","Mar"},0)),INDEX(Trends!$C$5:$N$5,MATCH($C$2,{"Apr","May","Jun","Jul","Aug","Sep","Oct","Nov","Dec","Jan","Feb","Mar"},0)-1))-2,"↓ down","→ flat"))),"–") -> → flat | M10: =IFERROR(IF(MIN('KRA H - Health Service Deliver'!$U$5:$U$16)<0.7,INDEX('KRA H - Health Service Deliver'!$B$5:$B$16,MATCH(MIN('KRA H - Health Service Deliver'!$U$5:$U$16),'KRA H - Health Service Deliver'!$U$5:$U$16,0)),"–"),"–") -> PHC Functionality Score (% of PHCs scoring ≥70% on 6-parameter audit) | N10: See Action Tracker
A11: 2 | B11: E – Education Attendance & Outcomes | C11: DDSE (Deputy Director, School Education) | D11: 12 | E11: 12 | F11: =COUNTIF('KRA E - Education Attendance &'!$V$5:$V$16,"GREEN") -> 0 | G11: =COUNTIF('KRA E - Education Attendance &'!$V$5:$V$16,"YELLOW") -> 0 | H11: =COUNTIF('KRA E - Education Attendance &'!$V$5:$V$16,"RED") -> 12 | I11: =IFERROR(AVERAGEIF('KRA E - Education Attendance &'!$U$5:$U$16,">=0"),0) -> 0 | J11: =IFERROR(MIN(100,AVERAGEIF('KRA E - Education Attendance &'!$U$5:$U$16,">=0")*100),0) -> 0 | K11: =IF(J11>=90,"GREEN",IF(J11>=70,"YELLOW","RED")) -> RED | L11: =IFERROR(IF(OR(INDEX(Trends!$C$6:$N$6,MATCH($C$2,{"Apr","May","Jun","Jul","Aug","Sep","Oct","Nov","Dec","Jan","Feb","Mar"},0))="",IF(MATCH($C$2,{"Apr","May","Jun","Jul","Aug","Sep","Oct","Nov","Dec","Jan","Feb","Mar"},0)<=1,INDEX(Trends!$C$6:$N$6,MATCH($C$2,{"Apr","May","Jun","Jul","Aug","Sep","Oct","Nov","Dec","Jan","Feb","Mar"},0)),INDEX(Trends!$C$6:$N$6,MATCH($C$2,{"Apr","May","Jun","Jul","Aug","Sep","Oct","Nov","Dec","Jan","Feb","Mar"},0)-1))=""),"–",IF(INDEX(Trends!$C$6:$N$6,MATCH($C$2,{"Apr","May","Jun","Jul","Aug","Sep","Oct","Nov","Dec","Jan","Feb","Mar"},0))>IF(MATCH($C$2,{"Apr","May","Jun","Jul","Aug","Sep","Oct","Nov","Dec","Jan","Feb","Mar"},0)<=1,INDEX(Trends!$C$6:$N$6,MATCH($C$2,{"Apr","May","Jun","Jul","Aug","Sep","Oct","Nov","Dec","Jan","Feb","Mar"},0)),INDEX(Trends!$C$6:$N$6,MATCH($C$2,{"Apr","May","Jun","Jul","Aug","Sep","Oct","Nov","Dec","Jan","Feb","Mar"},0)-1))+2,"↑ up",IF(INDEX(Trends!$C$6:$N$6,MATCH($C$2,{"Apr","May","Jun","Jul","Aug","Sep","Oct","Nov","Dec","Jan","Feb","Mar"},0))<IF(MATCH($C$2,{"Apr","May","Jun","Jul","Aug","Sep","Oct","Nov","Dec","Jan","Feb","Mar"},0)<=1,INDEX(Trends!$C$6:$N$6,MATCH($C$2,{"Apr","May","Jun","Jul","Aug","Sep","Oct","Nov","Dec","Jan","Feb","Mar"},0)),INDEX(Trends!$C$6:$N$6,MATCH($C$2,{"Apr","May","Jun","Jul","Aug","Sep","Oct","Nov","Dec","Jan","Feb","Mar"},0)-1))-2,"↓ down","→ flat"))),"–") -> → flat | M11: =IFERROR(IF(MIN('KRA E - Education Attendance &'!$U$5:$U$16)<0.7,INDEX('KRA E - Education Attendance &'!$B$5:$B$16,MATCH(MIN('KRA E - Education Attendance &'!$U$5:$U$16),'KRA E - Education Attendance &'!$U$5:$U$16,0)),"–"),"–") -> Teacher Attendance Rate (avg across govt schools) | N11: See Action Tracker
A12: 3 | B12: A – Anganwadi & ECCE | C12: DPO (ICDS) | D12: 8 | E12: 9 | F12: =COUNTIF('KRA A - Anganwadi & ECCE'!$V$5:$V$13,"GREEN") -> 2 | G12: =COUNTIF('KRA A - Anganwadi & ECCE'!$V$5:$V$13,"YELLOW") -> 0 | H12: =COUNTIF('KRA A - Anganwadi & ECCE'!$V$5:$V$13,"RED") -> 7 | I12: =IFERROR(AVERAGEIF('KRA A - Anganwadi & ECCE'!$U$5:$U$13,">=0"),0) -> 0.33333333 | J12: =IFERROR(MIN(100,AVERAGEIF('KRA A - Anganwadi & ECCE'!$U$5:$U$13,">=0")*100),0) -> 33.333333 | K12: =IF(J12>=90,"GREEN",IF(J12>=70,"YELLOW","RED")) -> RED | L12: =IFERROR(IF(OR(INDEX(Trends!$C$7:$N$7,MATCH($C$2,{"Apr","May","Jun","Jul","Aug","Sep","Oct","Nov","Dec","Jan","Feb","Mar"},0))="",IF(MATCH($C$2,{"Apr","May","Jun","Jul","Aug","Sep","Oct","Nov","Dec","Jan","Feb","Mar"},0)<=1,INDEX(Trends!$C$7:$N$7,MATCH($C$2,{"Apr","May","Jun","Jul","Aug","Sep","Oct","Nov","Dec","Jan","Feb","Mar"},0)),INDEX(Trends!$C$7:$N$7,MATCH($C$2,{"Apr","May","Jun","Jul","Aug","Sep","Oct","Nov","Dec","Jan","Feb","Mar"},0)-1))=""),"–",IF(INDEX(Trends!$C$7:$N$7,MATCH($C$2,{"Apr","May","Jun","Jul","Aug","Sep","Oct","Nov","Dec","Jan","Feb","Mar"},0))>IF(MATCH($C$2,{"Apr","May","Jun","Jul","Aug","Sep","Oct","Nov","Dec","Jan","Feb","Mar"},0)<=1,INDEX(Trends!$C$7:$N$7,MATCH($C$2,{"Apr","May","Jun","Jul","Aug","Sep","Oct","Nov","Dec","Jan","Feb","Mar"},0)),INDEX(Trends!$C$7:$N$7,MATCH($C$2,{"Apr","May","Jun","Jul","Aug","Sep","Oct","Nov","Dec","Jan","Feb","Mar"},0)-1))+2,"↑ up",IF(INDEX(Trends!$C$7:$N$7,MATCH($C$2,{"Apr","May","Jun","Jul","Aug","Sep","Oct","Nov","Dec","Jan","Feb","Mar"},0))<IF(MATCH($C$2,{"Apr","May","Jun","Jul","Aug","Sep","Oct","Nov","Dec","Jan","Feb","Mar"},0)<=1,INDEX(Trends!$C$7:$N$7,MATCH($C$2,{"Apr","May","Jun","Jul","Aug","Sep","Oct","Nov","Dec","Jan","Feb","Mar"},0)),INDEX(Trends!$C$7:$N$7,MATCH($C$2,{"Apr","May","Jun","Jul","Aug","Sep","Oct","Nov","Dec","Jan","Feb","Mar"},0)-1))-2,"↓ down","→ flat"))),"–") -> → flat | M12: =IFERROR(IF(MIN('KRA A - Anganwadi & ECCE'!$U$5:$U$13)<0.7,INDEX('KRA A - Anganwadi & ECCE'!$B$5:$B$13,MATCH(MIN('KRA A - Anganwadi & ECCE'!$U$5:$U$13),'KRA A - Anganwadi & ECCE'!$U$5:$U$13,0)),"–"),"–") -> AWC Functionality Score (% scoring ≥70% on 5-parameter audit) | N12: See Action Tracker
A13: 4 | B13: D – Drug Demand-Reduction & Youth | C13: DC + DMO + SP (joint) | D13: 10 | E13: 8 | F13: =COUNTIF('KRA D - Drug Demand-Reduction '!$V$5:$V$12,"GREEN") -> 0 | G13: =COUNTIF('KRA D - Drug Demand-Reduction '!$V$5:$V$12,"YELLOW") -> 0 | H13: =COUNTIF('KRA D - Drug Demand-Reduction '!$V$5:$V$12,"RED") -> 8 | I13: =IFERROR(AVERAGEIF('KRA D - Drug Demand-Reduction '!$U$5:$U$12,">=0"),0) -> 0 | J13: =IFERROR(MIN(100,AVERAGEIF('KRA D - Drug Demand-Reduction '!$U$5:$U$12,">=0")*100),0) -> 0 | K13: =IF(J13>=90,"GREEN",IF(J13>=70,"YELLOW","RED")) -> RED | L13: =IFERROR(IF(OR(INDEX(Trends!$C$8:$N$8,MATCH($C$2,{"Apr","May","Jun","Jul","Aug","Sep","Oct","Nov","Dec","Jan","Feb","Mar"},0))="",IF(MATCH($C$2,{"Apr","May","Jun","Jul","Aug","Sep","Oct","Nov","Dec","Jan","Feb","Mar"},0)<=1,INDEX(Trends!$C$8:$N$8,MATCH($C$2,{"Apr","May","Jun","Jul","Aug","Sep","Oct","Nov","Dec","Jan","Feb","Mar"},0)),INDEX(Trends!$C$8:$N$8,MATCH($C$2,{"Apr","May","Jun","Jul","Aug","Sep","Oct","Nov","Dec","Jan","Feb","Mar"},0)-1))=""),"–",IF(INDEX(Trends!$C$8:$N$8,MATCH($C$2,{"Apr","May","Jun","Jul","Aug","Sep","Oct","Nov","Dec","Jan","Feb","Mar"},0))>IF(MATCH($C$2,{"Apr","May","Jun","Jul","Aug","Sep","Oct","Nov","Dec","Jan","Feb","Mar"},0)<=1,INDEX(Trends!$C$8:$N$8,MATCH($C$2,{"Apr","May","Jun","Jul","Aug","Sep","Oct","Nov","Dec","Jan","Feb","Mar"},0)),INDEX(Trends!$C$8:$N$8,MATCH($C$2,{"Apr","May","Jun","Jul","Aug","Sep","Oct","Nov","Dec","Jan","Feb","Mar"},0)-1))+2,"↑ up",IF(INDEX(Trends!$C$8:$N$8,MATCH($C$2,{"Apr","May","Jun","Jul","Aug","Sep","Oct","Nov","Dec","Jan","Feb","Mar"},0))<IF(MATCH($C$2,{"Apr","May","Jun","Jul","Aug","Sep","Oct","Nov","Dec","Jan","Feb","Mar"},0)<=1,INDEX(Trends!$C$8:$N$8,MATCH($C$2,{"Apr","May","Jun","Jul","Aug","Sep","Oct","Nov","Dec","Jan","Feb","Mar"},0)),INDEX(Trends!$C$8:$N$8,MATCH($C$2,{"Apr","May","Jun","Jul","Aug","Sep","Oct","Nov","Dec","Jan","Feb","Mar"},0)-1))-2,"↓ down","→ flat"))),"–") -> → flat | M13: =IFERROR(IF(MIN('KRA D - Drug Demand-Reduction '!$U$5:$U$12)<0.7,INDEX('KRA D - Drug Demand-Reduction '!$B$5:$B$12,MATCH(MIN('KRA D - Drug Demand-Reduction '!$U$5:$U$12),'KRA D - Drug Demand-Reduction '!$U$5:$U$12,0)),"–"),"–") -> New Patients Inducted into De-addiction Programme | N13: See Action Tracker
A14: 5 | B14: S – Sanitation, Cleanliness & Urban Services | C14: TMC / Municipal Cmsr + SDO | D14: 6 | E14: 6 | F14: =COUNTIF('KRA S - Sanitation, Cleanlines'!$V$5:$V$10,"GREEN") -> 0 | G14: =COUNTIF('KRA S - Sanitation, Cleanlines'!$V$5:$V$10,"YELLOW") -> 0 | H14: =COUNTIF('KRA S - Sanitation, Cleanlines'!$V$5:$V$10,"RED") -> 6 | I14: =IFERROR(AVERAGEIF('KRA S - Sanitation, Cleanlines'!$U$5:$U$10,">=0"),0) -> 0 | J14: =IFERROR(MIN(100,AVERAGEIF('KRA S - Sanitation, Cleanlines'!$U$5:$U$10,">=0")*100),0) -> 0 | K14: =IF(J14>=90,"GREEN",IF(J14>=70,"YELLOW","RED")) -> RED | L14: =IFERROR(IF(OR(INDEX(Trends!$C$9:$N$9,MATCH($C$2,{"Apr","May","Jun","Jul","Aug","Sep","Oct","Nov","Dec","Jan","Feb","Mar"},0))="",IF(MATCH($C$2,{"Apr","May","Jun","Jul","Aug","Sep","Oct","Nov","Dec","Jan","Feb","Mar"},0)<=1,INDEX(Trends!$C$9:$N$9,MATCH($C$2,{"Apr","May","Jun","Jul","Aug","Sep","Oct","Nov","Dec","Jan","Feb","Mar"},0)),INDEX(Trends!$C$9:$N$9,MATCH($C$2,{"Apr","May","Jun","Jul","Aug","Sep","Oct","Nov","Dec","Jan","Feb","Mar"},0)-1))=""),"–",IF(INDEX(Trends!$C$9:$N$9,MATCH($C$2,{"Apr","May","Jun","Jul","Aug","Sep","Oct","Nov","Dec","Jan","Feb","Mar"},0))>IF(MATCH($C$2,{"Apr","May","Jun","Jul","Aug","Sep","Oct","Nov","Dec","Jan","Feb","Mar"},0)<=1,INDEX(Trends!$C$9:$N$9,MATCH($C$2,{"Apr","May","Jun","Jul","Aug","Sep","Oct","Nov","Dec","Jan","Feb","Mar"},0)),INDEX(Trends!$C$9:$N$9,MATCH($C$2,{"Apr","May","Jun","Jul","Aug","Sep","Oct","Nov","Dec","Jan","Feb","Mar"},0)-1))+2,"↑ up",IF(INDEX(Trends!$C$9:$N$9,MATCH($C$2,{"Apr","May","Jun","Jul","Aug","Sep","Oct","Nov","Dec","Jan","Feb","Mar"},0))<IF(MATCH($C$2,{"Apr","May","Jun","Jul","Aug","Sep","Oct","Nov","Dec","Jan","Feb","Mar"},0)<=1,INDEX(Trends!$C$9:$N$9,MATCH($C$2,{"Apr","May","Jun","Jul","Aug","Sep","Oct","Nov","Dec","Jan","Feb","Mar"},0)),INDEX(Trends!$C$9:$N$9,MATCH($C$2,{"Apr","May","Jun","Jul","Aug","Sep","Oct","Nov","Dec","Jan","Feb","Mar"},0)-1))-2,"↓ down","→ flat"))),"–") -> → flat | M14: =IFERROR(IF(MIN('KRA S - Sanitation, Cleanlines'!$U$5:$U$10)<0.7,INDEX('KRA S - Sanitation, Cleanlines'!$B$5:$B$10,MATCH(MIN('KRA S - Sanitation, Cleanlines'!$U$5:$U$10),'KRA S - Sanitation, Cleanlines'!$U$5:$U$10,0)),"–"),"–") -> ODF-Plus Villages Declared & Sustained (cumulative) | N14: See Action Tracker
A15: 6 | B15: I – Infrastructure, Roads & Connectivity | C15: PWD SE + PMGSY PIA | D15: 8 | E15: 8 | F15: =COUNTIF('KRA I - Infrastructure, Roads '!$V$5:$V$12,"GREEN") -> 2 | G15: =COUNTIF('KRA I - Infrastructure, Roads '!$V$5:$V$12,"YELLOW") -> 0 | H15: =COUNTIF('KRA I - Infrastructure, Roads '!$V$5:$V$12,"RED") -> 6 | I15: =IFERROR(AVERAGEIF('KRA I - Infrastructure, Roads '!$U$5:$U$12,">=0"),0) -> 0.375 | J15: =IFERROR(MIN(100,AVERAGEIF('KRA I - Infrastructure, Roads '!$U$5:$U$12,">=0")*100),0) -> 37.5 | K15: =IF(J15>=90,"GREEN",IF(J15>=70,"YELLOW","RED")) -> RED | L15: =IFERROR(IF(OR(INDEX(Trends!$C$10:$N$10,MATCH($C$2,{"Apr","May","Jun","Jul","Aug","Sep","Oct","Nov","Dec","Jan","Feb","Mar"},0))="",IF(MATCH($C$2,{"Apr","May","Jun","Jul","Aug","Sep","Oct","Nov","Dec","Jan","Feb","Mar"},0)<=1,INDEX(Trends!$C$10:$N$10,MATCH($C$2,{"Apr","May","Jun","Jul","Aug","Sep","Oct","Nov","Dec","Jan","Feb","Mar"},0)),INDEX(Trends!$C$10:$N$10,MATCH($C$2,{"Apr","May","Jun","Jul","Aug","Sep","Oct","Nov","Dec","Jan","Feb","Mar"},0)-1))=""),"–",IF(INDEX(Trends!$C$10:$N$10,MATCH($C$2,{"Apr","May","Jun","Jul","Aug","Sep","Oct","Nov","Dec","Jan","Feb","Mar"},0))>IF(MATCH($C$2,{"Apr","May","Jun","Jul","Aug","Sep","Oct","Nov","Dec","Jan","Feb","Mar"},0)<=1,INDEX(Trends!$C$10:$N$10,MATCH($C$2,{"Apr","May","Jun","Jul","Aug","Sep","Oct","Nov","Dec","Jan","Feb","Mar"},0)),INDEX(Trends!$C$10:$N$10,MATCH($C$2,{"Apr","May","Jun","Jul","Aug","Sep","Oct","Nov","Dec","Jan","Feb","Mar"},0)-1))+2,"↑ up",IF(INDEX(Trends!$C$10:$N$10,MATCH($C$2,{"Apr","May","Jun","Jul","Aug","Sep","Oct","Nov","Dec","Jan","Feb","Mar"},0))<IF(MATCH($C$2,{"Apr","May","Jun","Jul","Aug","Sep","Oct","Nov","Dec","Jan","Feb","Mar"},0)<=1,INDEX(Trends!$C$10:$N$10,MATCH($C$2,{"Apr","May","Jun","Jul","Aug","Sep","Oct","Nov","Dec","Jan","Feb","Mar"},0)),INDEX(Trends!$C$10:$N$10,MATCH($C$2,{"Apr","May","Jun","Jul","Aug","Sep","Oct","Nov","Dec","Jan","Feb","Mar"},0)-1))-2,"↓ down","→ flat"))),"–") -> → flat | M15: =IFERROR(IF(MIN('KRA I - Infrastructure, Roads '!$U$5:$U$12)<0.7,INDEX('KRA I - Infrastructure, Roads '!$B$5:$B$12,MATCH(MIN('KRA I - Infrastructure, Roads '!$U$5:$U$12),'KRA I - Infrastructure, Roads '!$U$5:$U$12,0)),"–"),"–") -> PWD Road Condition (% rated passable, dry season) | N15: See Action Tracker
A16: 7 | B16: W – Power Supply & Distribution | C16: Executive Engineer (Power) | D16: 6 | E16: 10 | F16: =COUNTIF('KRA W - Power'!$V$5:$V$14,"GREEN") -> 3 | G16: =COUNTIF('KRA W - Power'!$V$5:$V$14,"YELLOW") -> 0 | H16: =COUNTIF('KRA W - Power'!$V$5:$V$14,"RED") -> 7 | I16: =IFERROR(AVERAGEIF('KRA W - Power'!$U$5:$U$14,">=0"),0) -> 0.45 | J16: =IFERROR(MIN(100,AVERAGEIF('KRA W - Power'!$U$5:$U$14,">=0")*100),0) -> 45 | K16: =IF(J16>=90,"GREEN",IF(J16>=70,"YELLOW","RED")) -> RED | L16: =IFERROR(IF(OR(INDEX(Trends!$C$11:$N$11,MATCH($C$2,{"Apr","May","Jun","Jul","Aug","Sep","Oct","Nov","Dec","Jan","Feb","Mar"},0))="",IF(MATCH($C$2,{"Apr","May","Jun","Jul","Aug","Sep","Oct","Nov","Dec","Jan","Feb","Mar"},0)<=1,INDEX(Trends!$C$11:$N$11,MATCH($C$2,{"Apr","May","Jun","Jul","Aug","Sep","Oct","Nov","Dec","Jan","Feb","Mar"},0)),INDEX(Trends!$C$11:$N$11,MATCH($C$2,{"Apr","May","Jun","Jul","Aug","Sep","Oct","Nov","Dec","Jan","Feb","Mar"},0)-1))=""),"–",IF(INDEX(Trends!$C$11:$N$11,MATCH($C$2,{"Apr","May","Jun","Jul","Aug","Sep","Oct","Nov","Dec","Jan","Feb","Mar"},0))>IF(MATCH($C$2,{"Apr","May","Jun","Jul","Aug","Sep","Oct","Nov","Dec","Jan","Feb","Mar"},0)<=1,INDEX(Trends!$C$11:$N$11,MATCH($C$2,{"Apr","May","Jun","Jul","Aug","Sep","Oct","Nov","Dec","Jan","Feb","Mar"},0)),INDEX(Trends!$C$11:$N$11,MATCH($C$2,{"Apr","May","Jun","Jul","Aug","Sep","Oct","Nov","Dec","Jan","Feb","Mar"},0)-1))+2,"↑ up",IF(INDEX(Trends!$C$11:$N$11,MATCH($C$2,{"Apr","May","Jun","Jul","Aug","Sep","Oct","Nov","Dec","Jan","Feb","Mar"},0))<IF(MATCH($C$2,{"Apr","May","Jun","Jul","Aug","Sep","Oct","Nov","Dec","Jan","Feb","Mar"},0)<=1,INDEX(Trends!$C$11:$N$11,MATCH($C$2,{"Apr","May","Jun","Jul","Aug","Sep","Oct","Nov","Dec","Jan","Feb","Mar"},0)),INDEX(Trends!$C$11:$N$11,MATCH($C$2,{"Apr","May","Jun","Jul","Aug","Sep","Oct","Nov","Dec","Jan","Feb","Mar"},0)-1))-2,"↓ down","→ flat"))),"–") -> → flat | M16: =IFERROR(IF(MIN('KRA W - Power'!$U$5:$U$14)<0.7,INDEX('KRA W - Power'!$B$5:$B$14,MATCH(MIN('KRA W - Power'!$U$5:$U$14),'KRA W - Power'!$U$5:$U$14,0)),"–"),"–") -> Average Daily Power Supply Hours (district HQ + circle HQs) | N16: See Action Tracker
A17: 8 | B17: L – Law & Order, Public Safety | C17: Superintendent of Police | D17: 8 | E17: 8 | F17: =COUNTIF('KRA L - Law & Order, Public Sa'!$V$5:$V$12,"GREEN") -> 3 | G17: =COUNTIF('KRA L - Law & Order, Public Sa'!$V$5:$V$12,"YELLOW") -> 0 | H17: =COUNTIF('KRA L - Law & Order, Public Sa'!$V$5:$V$12,"RED") -> 5 | I17: =IFERROR(AVERAGEIF('KRA L - Law & Order, Public Sa'!$U$5:$U$12,">=0"),0) -> 0.5 | J17: =IFERROR(MIN(100,AVERAGEIF('KRA L - Law & Order, Public Sa'!$U$5:$U$12,">=0")*100),0) -> 50 | K17: =IF(J17>=90,"GREEN",IF(J17>=70,"YELLOW","RED")) -> RED | L17: =IFERROR(IF(OR(INDEX(Trends!$C$12:$N$12,MATCH($C$2,{"Apr","May","Jun","Jul","Aug","Sep","Oct","Nov","Dec","Jan","Feb","Mar"},0))="",IF(MATCH($C$2,{"Apr","May","Jun","Jul","Aug","Sep","Oct","Nov","Dec","Jan","Feb","Mar"},0)<=1,INDEX(Trends!$C$12:$N$12,MATCH($C$2,{"Apr","May","Jun","Jul","Aug","Sep","Oct","Nov","Dec","Jan","Feb","Mar"},0)),INDEX(Trends!$C$12:$N$12,MATCH($C$2,{"Apr","May","Jun","Jul","Aug","Sep","Oct","Nov","Dec","Jan","Feb","Mar"},0)-1))=""),"–",IF(INDEX(Trends!$C$12:$N$12,MATCH($C$2,{"Apr","May","Jun","Jul","Aug","Sep","Oct","Nov","Dec","Jan","Feb","Mar"},0))>IF(MATCH($C$2,{"Apr","May","Jun","Jul","Aug","Sep","Oct","Nov","Dec","Jan","Feb","Mar"},0)<=1,INDEX(Trends!$C$12:$N$12,MATCH($C$2,{"Apr","May","Jun","Jul","Aug","Sep","Oct","Nov","Dec","Jan","Feb","Mar"},0)),INDEX(Trends!$C$12:$N$12,MATCH($C$2,{"Apr","May","Jun","Jul","Aug","Sep","Oct","Nov","Dec","Jan","Feb","Mar"},0)-1))+2,"↑ up",IF(INDEX(Trends!$C$12:$N$12,MATCH($C$2,{"Apr","May","Jun","Jul","Aug","Sep","Oct","Nov","Dec","Jan","Feb","Mar"},0))<IF(MATCH($C$2,{"Apr","May","Jun","Jul","Aug","Sep","Oct","Nov","Dec","Jan","Feb","Mar"},0)<=1,INDEX(Trends!$C$12:$N$12,MATCH($C$2,{"Apr","May","Jun","Jul","Aug","Sep","Oct","Nov","Dec","Jan","Feb","Mar"},0)),INDEX(Trends!$C$12:$N$12,MATCH($C$2,{"Apr","May","Jun","Jul","Aug","Sep","Oct","Nov","Dec","Jan","Feb","Mar"},0)-1))-2,"↓ down","→ flat"))),"–") -> → flat | M17: =IFERROR(IF(MIN('KRA L - Law & Order, Public Sa'!$U$5:$U$12)<0.7,INDEX('KRA L - Law & Order, Public Sa'!$B$5:$B$12,MATCH(MIN('KRA L - Law & Order, Public Sa'!$U$5:$U$12),'KRA L - Law & Order, Public Sa'!$U$5:$U$12,0)),"–"),"–") -> FIR Registration Compliance (% of complaints leading to FIR) | N17: See Action Tracker
A18: 9 | B18: G – Agriculture, Horticulture & Allied | C18: DAO + DHO + DPM-NRLM | D18: 8 | E18: 10 | F18: =COUNTIF('KRA G - Agriculture, Horticult'!$V$5:$V$14,"GREEN") -> 0 | G18: =COUNTIF('KRA G - Agriculture, Horticult'!$V$5:$V$14,"YELLOW") -> 0 | H18: =COUNTIF('KRA G - Agriculture, Horticult'!$V$5:$V$14,"RED") -> 10 | I18: =IFERROR(AVERAGEIF('KRA G - Agriculture, Horticult'!$U$5:$U$14,">=0"),0) -> 0 | J18: =IFERROR(MIN(100,AVERAGEIF('KRA G - Agriculture, Horticult'!$U$5:$U$14,">=0")*100),0) -> 0 | K18: =IF(J18>=90,"GREEN",IF(J18>=70,"YELLOW","RED")) -> RED | L18: =IFERROR(IF(OR(INDEX(Trends!$C$13:$N$13,MATCH($C$2,{"Apr","May","Jun","Jul","Aug","Sep","Oct","Nov","Dec","Jan","Feb","Mar"},0))="",IF(MATCH($C$2,{"Apr","May","Jun","Jul","Aug","Sep","Oct","Nov","Dec","Jan","Feb","Mar"},0)<=1,INDEX(Trends!$C$13:$N$13,MATCH($C$2,{"Apr","May","Jun","Jul","Aug","Sep","Oct","Nov","Dec","Jan","Feb","Mar"},0)),INDEX(Trends!$C$13:$N$13,MATCH($C$2,{"Apr","May","Jun","Jul","Aug","Sep","Oct","Nov","Dec","Jan","Feb","Mar"},0)-1))=""),"–",IF(INDEX(Trends!$C$13:$N$13,MATCH($C$2,{"Apr","May","Jun","Jul","Aug","Sep","Oct","Nov","Dec","Jan","Feb","Mar"},0))>IF(MATCH($C$2,{"Apr","May","Jun","Jul","Aug","Sep","Oct","Nov","Dec","Jan","Feb","Mar"},0)<=1,INDEX(Trends!$C$13:$N$13,MATCH($C$2,{"Apr","May","Jun","Jul","Aug","Sep","Oct","Nov","Dec","Jan","Feb","Mar"},0)),INDEX(Trends!$C$13:$N$13,MATCH($C$2,{"Apr","May","Jun","Jul","Aug","Sep","Oct","Nov","Dec","Jan","Feb","Mar"},0)-1))+2,"↑ up",IF(INDEX(Trends!$C$13:$N$13,MATCH($C$2,{"Apr","May","Jun","Jul","Aug","Sep","Oct","Nov","Dec","Jan","Feb","Mar"},0))<IF(MATCH($C$2,{"Apr","May","Jun","Jul","Aug","Sep","Oct","Nov","Dec","Jan","Feb","Mar"},0)<=1,INDEX(Trends!$C$13:$N$13,MATCH($C$2,{"Apr","May","Jun","Jul","Aug","Sep","Oct","Nov","Dec","Jan","Feb","Mar"},0)),INDEX(Trends!$C$13:$N$13,MATCH($C$2,{"Apr","May","Jun","Jul","Aug","Sep","Oct","Nov","Dec","Jan","Feb","Mar"},0)-1))-2,"↓ down","→ flat"))),"–") -> → flat | M18: =IFERROR(IF(MIN('KRA G - Agriculture, Horticult'!$U$5:$U$14)<0.7,INDEX('KRA G - Agriculture, Horticult'!$B$5:$B$14,MATCH(MIN('KRA G - Agriculture, Horticult'!$U$5:$U$14),'KRA G - Agriculture, Horticult'!$U$5:$U$14,0)),"–"),"–") -> Farmer Field Demonstration Plots Active | N18: See Action Tracker
A19: 10 | B19: C – Convergence & Saturation Villages | C19: DC (chair) + multi-departmental | D19: 6 | E19: 8 | F19: =COUNTIF('KRA C - Convergence & Saturati'!$V$5:$V$12,"GREEN") -> 1 | G19: =COUNTIF('KRA C - Convergence & Saturati'!$V$5:$V$12,"YELLOW") -> 0 | H19: =COUNTIF('KRA C - Convergence & Saturati'!$V$5:$V$12,"RED") -> 7 | I19: =IFERROR(AVERAGEIF('KRA C - Convergence & Saturati'!$U$5:$U$12,">=0"),0) -> 0.125 | J19: =IFERROR(MIN(100,AVERAGEIF('KRA C - Convergence & Saturati'!$U$5:$U$12,">=0")*100),0) -> 12.5 | K19: =IF(J19>=90,"GREEN",IF(J19>=70,"YELLOW","RED")) -> RED | L19: =IFERROR(IF(OR(INDEX(Trends!$C$14:$N$14,MATCH($C$2,{"Apr","May","Jun","Jul","Aug","Sep","Oct","Nov","Dec","Jan","Feb","Mar"},0))="",IF(MATCH($C$2,{"Apr","May","Jun","Jul","Aug","Sep","Oct","Nov","Dec","Jan","Feb","Mar"},0)<=1,INDEX(Trends!$C$14:$N$14,MATCH($C$2,{"Apr","May","Jun","Jul","Aug","Sep","Oct","Nov","Dec","Jan","Feb","Mar"},0)),INDEX(Trends!$C$14:$N$14,MATCH($C$2,{"Apr","May","Jun","Jul","Aug","Sep","Oct","Nov","Dec","Jan","Feb","Mar"},0)-1))=""),"–",IF(INDEX(Trends!$C$14:$N$14,MATCH($C$2,{"Apr","May","Jun","Jul","Aug","Sep","Oct","Nov","Dec","Jan","Feb","Mar"},0))>IF(MATCH($C$2,{"Apr","May","Jun","Jul","Aug","Sep","Oct","Nov","Dec","Jan","Feb","Mar"},0)<=1,INDEX(Trends!$C$14:$N$14,MATCH($C$2,{"Apr","May","Jun","Jul","Aug","Sep","Oct","Nov","Dec","Jan","Feb","Mar"},0)),INDEX(Trends!$C$14:$N$14,MATCH($C$2,{"Apr","May","Jun","Jul","Aug","Sep","Oct","Nov","Dec","Jan","Feb","Mar"},0)-1))+2,"↑ up",IF(INDEX(Trends!$C$14:$N$14,MATCH($C$2,{"Apr","May","Jun","Jul","Aug","Sep","Oct","Nov","Dec","Jan","Feb","Mar"},0))<IF(MATCH($C$2,{"Apr","May","Jun","Jul","Aug","Sep","Oct","Nov","Dec","Jan","Feb","Mar"},0)<=1,INDEX(Trends!$C$14:$N$14,MATCH($C$2,{"Apr","May","Jun","Jul","Aug","Sep","Oct","Nov","Dec","Jan","Feb","Mar"},0)),INDEX(Trends!$C$14:$N$14,MATCH($C$2,{"Apr","May","Jun","Jul","Aug","Sep","Oct","Nov","Dec","Jan","Feb","Mar"},0)-1))-2,"↓ down","→ flat"))),"–") -> → flat | M19: =IFERROR(IF(MIN('KRA C - Convergence & Saturati'!$U$5:$U$12)<0.7,INDEX('KRA C - Convergence & Saturati'!$B$5:$B$12,MATCH(MIN('KRA C - Convergence & Saturati'!$U$5:$U$12),'KRA C - Convergence & Saturati'!$U$5:$U$12,0)),"–"),"–") -> Saturation Villages Where Camp Held (cumulative) | N19: See Action Tracker
A20: 11 | B20: R – Revenue & Land | C20: Revenue Officer + COs | D20: 6 | E20: 5 | F20: =COUNTIF('KRA R - Revenue, Land & Citize'!$V$5:$V$9,"GREEN") -> 1 | G20: =COUNTIF('KRA R - Revenue, Land & Citize'!$V$5:$V$9,"YELLOW") -> 0 | H20: =COUNTIF('KRA R - Revenue, Land & Citize'!$V$5:$V$9,"RED") -> 4 | I20: =IFERROR(AVERAGEIF('KRA R - Revenue, Land & Citize'!$U$5:$U$9,">=0"),0) -> 0.3 | J20: =IFERROR(MIN(100,AVERAGEIF('KRA R - Revenue, Land & Citize'!$U$5:$U$9,">=0")*100),0) -> 30 | K20: =IF(J20>=90,"GREEN",IF(J20>=70,"YELLOW","RED")) -> RED | L20: =IFERROR(IF(OR(INDEX(Trends!$C$15:$N$15,MATCH($C$2,{"Apr","May","Jun","Jul","Aug","Sep","Oct","Nov","Dec","Jan","Feb","Mar"},0))="",IF(MATCH($C$2,{"Apr","May","Jun","Jul","Aug","Sep","Oct","Nov","Dec","Jan","Feb","Mar"},0)<=1,INDEX(Trends!$C$15:$N$15,MATCH($C$2,{"Apr","May","Jun","Jul","Aug","Sep","Oct","Nov","Dec","Jan","Feb","Mar"},0)),INDEX(Trends!$C$15:$N$15,MATCH($C$2,{"Apr","May","Jun","Jul","Aug","Sep","Oct","Nov","Dec","Jan","Feb","Mar"},0)-1))=""),"–",IF(INDEX(Trends!$C$15:$N$15,MATCH($C$2,{"Apr","May","Jun","Jul","Aug","Sep","Oct","Nov","Dec","Jan","Feb","Mar"},0))>IF(MATCH($C$2,{"Apr","May","Jun","Jul","Aug","Sep","Oct","Nov","Dec","Jan","Feb","Mar"},0)<=1,INDEX(Trends!$C$15:$N$15,MATCH($C$2,{"Apr","May","Jun","Jul","Aug","Sep","Oct","Nov","Dec","Jan","Feb","Mar"},0)),INDEX(Trends!$C$15:$N$15,MATCH($C$2,{"Apr","May","Jun","Jul","Aug","Sep","Oct","Nov","Dec","Jan","Feb","Mar"},0)-1))+2,"↑ up",IF(INDEX(Trends!$C$15:$N$15,MATCH($C$2,{"Apr","May","Jun","Jul","Aug","Sep","Oct","Nov","Dec","Jan","Feb","Mar"},0))<IF(MATCH($C$2,{"Apr","May","Jun","Jul","Aug","Sep","Oct","Nov","Dec","Jan","Feb","Mar"},0)<=1,INDEX(Trends!$C$15:$N$15,MATCH($C$2,{"Apr","May","Jun","Jul","Aug","Sep","Oct","Nov","Dec","Jan","Feb","Mar"},0)),INDEX(Trends!$C$15:$N$15,MATCH($C$2,{"Apr","May","Jun","Jul","Aug","Sep","Oct","Nov","Dec","Jan","Feb","Mar"},0)-1))-2,"↓ down","→ flat"))),"–") -> → flat | M20: =IFERROR(IF(MIN('KRA R - Revenue, Land & Citize'!$U$5:$U$9)<0.7,INDEX('KRA R - Revenue, Land & Citize'!$B$5:$B$9,MATCH(MIN('KRA R - Revenue, Land & Citize'!$U$5:$U$9),'KRA R - Revenue, Land & Citize'!$U$5:$U$9,0)),"–"),"–") -> Land Mutation Cases Disposed Within 30 Days | N20: See Action Tracker
A21: 12 | B21: J – Jan Suvidha (Certificates & Services) | C21: OIC, Jan Suvidha (DC Office) | D21: 6 | E21: 12 | F21: =COUNTIF('KRA J - Jan Suvidha Branch'!$V$5:$V$16,"GREEN") -> 2 | G21: =COUNTIF('KRA J - Jan Suvidha Branch'!$V$5:$V$16,"YELLOW") -> 0 | H21: =COUNTIF('KRA J - Jan Suvidha Branch'!$V$5:$V$16,"RED") -> 10 | I21: =IFERROR(AVERAGEIF('KRA J - Jan Suvidha Branch'!$U$5:$U$16,">=0"),0) -> 0.25 | J21: =IFERROR(MIN(100,AVERAGEIF('KRA J - Jan Suvidha Branch'!$U$5:$U$16,">=0")*100),0) -> 25 | K21: =IF(J21>=90,"GREEN",IF(J21>=70,"YELLOW","RED")) -> RED | L21: =IFERROR(IF(OR(INDEX(Trends!$C$16:$N$16,MATCH($C$2,{"Apr","May","Jun","Jul","Aug","Sep","Oct","Nov","Dec","Jan","Feb","Mar"},0))="",IF(MATCH($C$2,{"Apr","May","Jun","Jul","Aug","Sep","Oct","Nov","Dec","Jan","Feb","Mar"},0)<=1,INDEX(Trends!$C$16:$N$16,MATCH($C$2,{"Apr","May","Jun","Jul","Aug","Sep","Oct","Nov","Dec","Jan","Feb","Mar"},0)),INDEX(Trends!$C$16:$N$16,MATCH($C$2,{"Apr","May","Jun","Jul","Aug","Sep","Oct","Nov","Dec","Jan","Feb","Mar"},0)-1))=""),"–",IF(INDEX(Trends!$C$16:$N$16,MATCH($C$2,{"Apr","May","Jun","Jul","Aug","Sep","Oct","Nov","Dec","Jan","Feb","Mar"},0))>IF(MATCH($C$2,{"Apr","May","Jun","Jul","Aug","Sep","Oct","Nov","Dec","Jan","Feb","Mar"},0)<=1,INDEX(Trends!$C$16:$N$16,MATCH($C$2,{"Apr","May","Jun","Jul","Aug","Sep","Oct","Nov","Dec","Jan","Feb","Mar"},0)),INDEX(Trends!$C$16:$N$16,MATCH($C$2,{"Apr","May","Jun","Jul","Aug","Sep","Oct","Nov","Dec","Jan","Feb","Mar"},0)-1))+2,"↑ up",IF(INDEX(Trends!$C$16:$N$16,MATCH($C$2,{"Apr","May","Jun","Jul","Aug","Sep","Oct","Nov","Dec","Jan","Feb","Mar"},0))<IF(MATCH($C$2,{"Apr","May","Jun","Jul","Aug","Sep","Oct","Nov","Dec","Jan","Feb","Mar"},0)<=1,INDEX(Trends!$C$16:$N$16,MATCH($C$2,{"Apr","May","Jun","Jul","Aug","Sep","Oct","Nov","Dec","Jan","Feb","Mar"},0)),INDEX(Trends!$C$16:$N$16,MATCH($C$2,{"Apr","May","Jun","Jul","Aug","Sep","Oct","Nov","Dec","Jan","Feb","Mar"},0)-1))-2,"↓ down","→ flat"))),"–") -> → flat | M21: =IFERROR(IF(MIN('KRA J - Jan Suvidha Branch'!$U$5:$U$16)<0.7,INDEX('KRA J - Jan Suvidha Branch'!$B$5:$B$16,MATCH(MIN('KRA J - Jan Suvidha Branch'!$U$5:$U$16),'KRA J - Jan Suvidha Branch'!$U$5:$U$16,0)),"–"),"–") -> ST (Scheduled Tribe) Certificate Issued Within 15 Days | N21: See Action Tracker
A22: 13 | B22: M – Disaster Management & Resilience | C22: District Disaster Mgmt Officer (DDMO) | D22: 4 | E22: 6 | F22: =COUNTIF('KRA M - Disaster Management & '!$V$5:$V$10,"GREEN") -> 0 | G22: =COUNTIF('KRA M - Disaster Management & '!$V$5:$V$10,"YELLOW") -> 0 | H22: =COUNTIF('KRA M - Disaster Management & '!$V$5:$V$10,"RED") -> 6 | I22: =IFERROR(AVERAGEIF('KRA M - Disaster Management & '!$U$5:$U$10,">=0"),0) -> 0 | J22: =IFERROR(MIN(100,AVERAGEIF('KRA M - Disaster Management & '!$U$5:$U$10,">=0")*100),0) -> 0 | K22: =IF(J22>=90,"GREEN",IF(J22>=70,"YELLOW","RED")) -> RED | L22: =IFERROR(IF(OR(INDEX(Trends!$C$17:$N$17,MATCH($C$2,{"Apr","May","Jun","Jul","Aug","Sep","Oct","Nov","Dec","Jan","Feb","Mar"},0))="",IF(MATCH($C$2,{"Apr","May","Jun","Jul","Aug","Sep","Oct","Nov","Dec","Jan","Feb","Mar"},0)<=1,INDEX(Trends!$C$17:$N$17,MATCH($C$2,{"Apr","May","Jun","Jul","Aug","Sep","Oct","Nov","Dec","Jan","Feb","Mar"},0)),INDEX(Trends!$C$17:$N$17,MATCH($C$2,{"Apr","May","Jun","Jul","Aug","Sep","Oct","Nov","Dec","Jan","Feb","Mar"},0)-1))=""),"–",IF(INDEX(Trends!$C$17:$N$17,MATCH($C$2,{"Apr","May","Jun","Jul","Aug","Sep","Oct","Nov","Dec","Jan","Feb","Mar"},0))>IF(MATCH($C$2,{"Apr","May","Jun","Jul","Aug","Sep","Oct","Nov","Dec","Jan","Feb","Mar"},0)<=1,INDEX(Trends!$C$17:$N$17,MATCH($C$2,{"Apr","May","Jun","Jul","Aug","Sep","Oct","Nov","Dec","Jan","Feb","Mar"},0)),INDEX(Trends!$C$17:$N$17,MATCH($C$2,{"Apr","May","Jun","Jul","Aug","Sep","Oct","Nov","Dec","Jan","Feb","Mar"},0)-1))+2,"↑ up",IF(INDEX(Trends!$C$17:$N$17,MATCH($C$2,{"Apr","May","Jun","Jul","Aug","Sep","Oct","Nov","Dec","Jan","Feb","Mar"},0))<IF(MATCH($C$2,{"Apr","May","Jun","Jul","Aug","Sep","Oct","Nov","Dec","Jan","Feb","Mar"},0)<=1,INDEX(Trends!$C$17:$N$17,MATCH($C$2,{"Apr","May","Jun","Jul","Aug","Sep","Oct","Nov","Dec","Jan","Feb","Mar"},0)),INDEX(Trends!$C$17:$N$17,MATCH($C$2,{"Apr","May","Jun","Jul","Aug","Sep","Oct","Nov","Dec","Jan","Feb","Mar"},0)-1))-2,"↓ down","→ flat"))),"–") -> → flat | M22: =IFERROR(IF(MIN('KRA M - Disaster Management & '!$U$5:$U$10)<0.7,INDEX('KRA M - Disaster Management & '!$B$5:$B$10,MATCH(MIN('KRA M - Disaster Management & '!$U$5:$U$10),'KRA M - Disaster Management & '!$U$5:$U$10,0)),"–"),"–") -> Disaster Preparedness Drills Conducted | N22: See Action Tracker
A23: 14 | B23: P – Process, People & Citizen Grievance | C23: DC Office | D23: 6 | E23: 10 | F23: =COUNTIF('KRA P - Process, People & Citi'!$V$5:$V$14,"GREEN") -> 1 | G23: =COUNTIF('KRA P - Process, People & Citi'!$V$5:$V$14,"YELLOW") -> 0 | H23: =COUNTIF('KRA P - Process, People & Citi'!$V$5:$V$14,"RED") -> 9 | I23: =IFERROR(AVERAGEIF('KRA P - Process, People & Citi'!$U$5:$U$14,">=0"),0) -> 0.15 | J23: =IFERROR(MIN(100,AVERAGEIF('KRA P - Process, People & Citi'!$U$5:$U$14,">=0")*100),0) -> 15 | K23: =IF(J23>=90,"GREEN",IF(J23>=70,"YELLOW","RED")) -> RED | L23: =IFERROR(IF(OR(INDEX(Trends!$C$18:$N$18,MATCH($C$2,{"Apr","May","Jun","Jul","Aug","Sep","Oct","Nov","Dec","Jan","Feb","Mar"},0))="",IF(MATCH($C$2,{"Apr","May","Jun","Jul","Aug","Sep","Oct","Nov","Dec","Jan","Feb","Mar"},0)<=1,INDEX(Trends!$C$18:$N$18,MATCH($C$2,{"Apr","May","Jun","Jul","Aug","Sep","Oct","Nov","Dec","Jan","Feb","Mar"},0)),INDEX(Trends!$C$18:$N$18,MATCH($C$2,{"Apr","May","Jun","Jul","Aug","Sep","Oct","Nov","Dec","Jan","Feb","Mar"},0)-1))=""),"–",IF(INDEX(Trends!$C$18:$N$18,MATCH($C$2,{"Apr","May","Jun","Jul","Aug","Sep","Oct","Nov","Dec","Jan","Feb","Mar"},0))>IF(MATCH($C$2,{"Apr","May","Jun","Jul","Aug","Sep","Oct","Nov","Dec","Jan","Feb","Mar"},0)<=1,INDEX(Trends!$C$18:$N$18,MATCH($C$2,{"Apr","May","Jun","Jul","Aug","Sep","Oct","Nov","Dec","Jan","Feb","Mar"},0)),INDEX(Trends!$C$18:$N$18,MATCH($C$2,{"Apr","May","Jun","Jul","Aug","Sep","Oct","Nov","Dec","Jan","Feb","Mar"},0)-1))+2,"↑ up",IF(INDEX(Trends!$C$18:$N$18,MATCH($C$2,{"Apr","May","Jun","Jul","Aug","Sep","Oct","Nov","Dec","Jan","Feb","Mar"},0))<IF(MATCH($C$2,{"Apr","May","Jun","Jul","Aug","Sep","Oct","Nov","Dec","Jan","Feb","Mar"},0)<=1,INDEX(Trends!$C$18:$N$18,MATCH($C$2,{"Apr","May","Jun","Jul","Aug","Sep","Oct","Nov","Dec","Jan","Feb","Mar"},0)),INDEX(Trends!$C$18:$N$18,MATCH($C$2,{"Apr","May","Jun","Jul","Aug","Sep","Oct","Nov","Dec","Jan","Feb","Mar"},0)-1))-2,"↓ down","→ flat"))),"–") -> → flat | M23: =IFERROR(IF(MIN('KRA P - Process, People & Citi'!$U$5:$U$14)<0.7,INDEX('KRA P - Process, People & Citi'!$B$5:$B$14,MATCH(MIN('KRA P - Process, People & Citi'!$U$5:$U$14),'KRA P - Process, People & Citi'!$U$5:$U$14,0)),"–"),"–") -> DC Field Days Completed | N23: See Action Tracker
B24: DISTRICT TOTAL | D24: 106 | E24: 124 | F24: =SUM(F10:F23) -> 18 | G24: =SUM(G10:G23) -> 0 | H24: =SUM(H10:H23) -> 106 | J24: =IFERROR(SUMPRODUCT(J10:J23,D10:D23)/SUM(D10:D23),0) -> 19.638365 | K24: =IF(J24>=90,"GREEN",IF(J24>=70,"YELLOW","RED")) -> RED
A26: HOW TO READ: Select the reporting month in cell C2. The entire dashboard updates automatically based on data entered in each KRA tab. GREEN = on track. YELLOW = monitor. RED = action plan required (see 'Action Tracker' tab).

Sheet KRA H - Health Service Deliver
A1: KRA H: Health Service Delivery
A2: Owner: DMO (District Medical Officer) | Weight in TPI: 12 | Indicators: 12
A4: # | B4: Indicator | C4: Unit | D4: Target | E4: Direction | F4: Freq | G4: Apr | H4: May | I4: Jun | J4: Jul | K4: Aug | L4: Sep | M4: Oct | N4: Nov | O4: Dec | P4: Jan | Q4: Feb | R4: Mar | T4: Current Actual | U4: Achievement % | V4: Status | W4: 3-mo Avg
A5: 1 | B5: PHC Functionality Score (% of PHCs scoring ≥70% on 6-parameter audit) | C5: % | D5: 80 | E5: ↑ higher better | F5: M | T5: =IFERROR(INDEX(G5:R5,MATCH(Dashboard!$C$2,{"Apr","May","Jun","Jul","Aug","Sep","Oct","Nov","Dec","Jan","Feb","Mar"},0)),"") -> 0 | U5: =IFERROR(IF(T5="","",IF(LEFT(E5,1)="↑",IF(D5=0,"",MIN(1.5,T5/D5)),IF(T5=0,IF(D5=0,1,1.5),MIN(1.5,D5/MAX(T5,0.0001))))),"") -> 0 | V5: =IF(U5="","–",IF(U5>=0.9,"GREEN",IF(U5>=0.7,"YELLOW","RED"))) -> RED | W5: =IFERROR(IF(T5="","",AVERAGE(OFFSET(G5,0,MAX(0,MATCH(Dashboard!$C$2,{"Apr","May","Jun","Jul","Aug","Sep","Oct","Nov","Dec","Jan","Feb","Mar"},0)-3),1,3))),"")
A6: 2 | B6: Institutional Delivery Rate | C6: % | D6: 65 | E6: ↑ higher better | F6: M | T6: =IFERROR(INDEX(G6:R6,MATCH(Dashboard!$C$2,{"Apr","May","Jun","Jul","Aug","Sep","Oct","Nov","Dec","Jan","Feb","Mar"},0)),"") -> 0 | U6: =IFERROR(IF(T6="","",IF(LEFT(E6,1)="↑",IF(D6=0,"",MIN(1.5,T6/D6)),IF(T6=0,IF(D6=0,1,1.5),MIN(1.5,D6/MAX(T6,0.0001))))),"") -> 0 | V6: =IF(U6="","–",IF(U6>=0.9,"GREEN",IF(U6>=0.7,"YELLOW","RED"))) -> RED | W6: =IFERROR(IF(T6="","",AVERAGE(OFFSET(G6,0,MAX(0,MATCH(Dashboard!$C$2,{"Apr","May","Jun","Jul","Aug","Sep","Oct","Nov","Dec","Jan","Feb","Mar"},0)-3),1,3))),"")
A7: 3 | B7: Full Immunisation Coverage (children 0-1 yr) | C7: % | D7: 90 | E7: ↑ higher better | F7: M | T7: =IFERROR(INDEX(G7:R7,MATCH(Dashboard!$C$2,{"Apr","May","Jun","Jul","Aug","Sep","Oct","Nov","Dec","Jan","Feb","Mar"},0)),"") -> 0 | U7: =IFERROR(IF(T7="","",IF(LEFT(E7,1)="↑",IF(D7=0,"",MIN(1.5,T7/D7)),IF(T7=0,IF(D7=0,1,1.5),MIN(1.5,D7/MAX(T7,0.0001))))),"") -> 0 | V7: =IF(U7="","–",IF(U7>=0.9,"GREEN",IF(U7>=0.7,"YELLOW","RED"))) -> RED | W7: =IFERROR(IF(T7="","",AVERAGE(OFFSET(G7,0,MAX(0,MATCH(Dashboard!$C$2,{"Apr","May","Jun","Jul","Aug","Sep","Oct","Nov","Dec","Jan","Feb","Mar"},0)-3),1,3))),"")
A8: 4 | B8: eSanjeevani Tele-OPD Consults per active SC | C8: count | D8: 40 | E8: ↑ higher better | F8: M | T8: =IFERROR(INDEX(G8:R8,MATCH(Dashboard!$C$2,{"Apr","May","Jun","Jul","Aug","Sep","Oct","Nov","Dec","Jan","Feb","Mar"},0)),"") -> 0 | U8: =IFERROR(IF(T8="","",IF(LEFT(E8,1)="↑",IF(D8=0,"",MIN(1.5,T8/D8)),IF(T8=0,IF(D8=0,1,1.5),MIN(1.5,D8/MAX(T8,0.0001))))),"") -> 0 | V8: =IF(U8="","–",IF(U8>=0.9,"GREEN",IF(U8>=0.7,"YELLOW","RED"))) -> RED | W8: =IFERROR(IF(T8="","",AVERAGE(OFFSET(G8,0,MAX(0,MATCH(Dashboard!$C$2,{"Apr","May","Jun","Jul","Aug","Sep","Oct","Nov","Dec","Jan","Feb","Mar"},0)-3),1,3))),"")
A9: 5 | B9: ANC 4 Visits Completed (% of registered pregnancies) | C9: % | D9: 75 | E9: ↑ higher better | F9: M | T9: =IFERROR(INDEX(G9:R9,MATCH(Dashboard!$C$2,{"Apr","May","Jun","Jul","Aug","Sep","Oct","Nov","Dec","Jan","Feb","Mar"},0)),"") -> 0 | U9: =IFERROR(IF(T9="","",IF(LEFT(E9,1)="↑",IF(D9=0,"",MIN(1.5,T9/D9)),IF(T9=0,IF(D9=0,1,1.5),MIN(1.5,D9/MAX(T9,0.0001))))),"") -> 0 | V9: =IF(U9="","–",IF(U9>=0.9,"GREEN",IF(U9>=0.7,"YELLOW","RED"))) -> RED | W9: =IFERROR(IF(T9="","",AVERAGE(OFFSET(G9,0,MAX(0,MATCH(Dashboard!$C$2,{"Apr","May","Jun","Jul","Aug","Sep","Oct","Nov","Dec","Jan","Feb","Mar"},0)-3),1,3))),"")
A10: 6 | B10: Ayushman Card Coverage in Priority Villages | C10: % | D10: 85 | E10: ↑ higher better | F10: M | T10: =IFERROR(INDEX(G10:R10,MATCH(Dashboard!$C$2,{"Apr","May","Jun","Jul","Aug","Sep","Oct","Nov","Dec","Jan","Feb","Mar"},0)),"") -> 0 | U10: =IFERROR(IF(T10="","",IF(LEFT(E10,1)="↑",IF(D10=0,"",MIN(1.5,T10/D10)),IF(T10=0,IF(D10=0,1,1.5),MIN(1.5,D10/MAX(T10,0.0001))))),"") -> 0 | V10: =IF(U10="","–",IF(U10>=0.9,"GREEN",IF(U10>=0.7,"YELLOW","RED"))) -> RED | W10: =IFERROR(IF(T10="","",AVERAGE(OFFSET(G10,0,MAX(0,MATCH(Dashboard!$C$2,{"Apr","May","Jun","Jul","Aug","Sep","Oct","Nov","Dec","Jan","Feb","Mar"},0)-3),1,3))),"")
A11: 7 | B11: Drug Stock-out Days at PHCs (cumulative across district) | C11: days | D11: 0 | E11: ↓ lower better | F11: M | T11: =IFERROR(INDEX(G11:R11,MATCH(Dashboard!$C$2,{"Apr","May","Jun","Jul","Aug","Sep","Oct","Nov","Dec","Jan","Feb","Mar"},0)),"") -> 0 | U11: =IFERROR(IF(T11="","",IF(LEFT(E11,1)="↑",IF(D11=0,"",MIN(1.5,T11/D11)),IF(T11=0,IF(D11=0,1,1.5),MIN(1.5,D11/MAX(T11,0.0001))))),"") -> 1 | V11: =IF(U11="","–",IF(U11>=0.9,"GREEN",IF(U11>=0.7,"YELLOW","RED"))) -> GREEN | W11: =IFERROR(IF(T11="","",AVERAGE(OFFSET(G11,0,MAX(0,MATCH(Dashboard!$C$2,{"Apr","May","Jun","Jul","Aug","Sep","Oct","Nov","Dec","Jan","Feb","Mar"},0)-3),1,3))),"")
A12: 8 | B12: OST (Opioid Substitution) Active Patients | C12: count | D12: 200 | E12: ↑ higher better | F12: M | T12: =IFERROR(INDEX(G12:R12,MATCH(Dashboard!$C$2,{"Apr","May","Jun","Jul","Aug","Sep","Oct","Nov","Dec","Jan","Feb","Mar"},0)),"") -> 0 | U12: =IFERROR(IF(T12="","",IF(LEFT(E12,1)="↑",IF(D12=0,"",MIN(1.5,T12/D12)),IF(T12=0,IF(D12=0,1,1.5),MIN(1.5,D12/MAX(T12,0.0001))))),"") -> 0 | V12: =IF(U12="","–",IF(U12>=0.9,"GREEN",IF(U12>=0.7,"YELLOW","RED"))) -> RED | W12: =IFERROR(IF(T12="","",AVERAGE(OFFSET(G12,0,MAX(0,MATCH(Dashboard!$C$2,{"Apr","May","Jun","Jul","Aug","Sep","Oct","Nov","Dec","Jan","Feb","Mar"},0)-3),1,3))),"")
A13: 9 | B13: De-addiction Centre Treatment Retention (3-month) | C13: % | D13: 60 | E13: ↑ higher better | F13: M | T13: =IFERROR(INDEX(G13:R13,MATCH(Dashboard!$C$2,{"Apr","May","Jun","Jul","Aug","Sep","Oct","Nov","Dec","Jan","Feb","Mar"},0)),"") -> 0 | U13: =IFERROR(IF(T13="","",IF(LEFT(E13,1)="↑",IF(D13=0,"",MIN(1.5,T13/D13)),IF(T13=0,IF(D13=0,1,1.5),MIN(1.5,D13/MAX(T13,0.0001))))),"") -> 0 | V13: =IF(U13="","–",IF(U13>=0.9,"GREEN",IF(U13>=0.7,"YELLOW","RED"))) -> RED | W13: =IFERROR(IF(T13="","",AVERAGE(OFFSET(G13,0,MAX(0,MATCH(Dashboard!$C$2,{"Apr","May","Jun","Jul","Aug","Sep","Oct","Nov","Dec","Jan","Feb","Mar"},0)-3),1,3))),"")
A14: 10 | B14: TB Case Notification Rate (per lakh population) | C14: rate | D14: 150 | E14: ↑ higher better | F14: M | T14: =IFERROR(INDEX(G14:R14,MATCH(Dashboard!$C$2,{"Apr","May","Jun","Jul","Aug","Sep","Oct","Nov","Dec","Jan","Feb","Mar"},0)),"") -> 0 | U14: =IFERROR(IF(T14="","",IF(LEFT(E14,1)="↑",IF(D14=0,"",MIN(1.5,T14/D14)),IF(T14=0,IF(D14=0,1,1.5),MIN(1.5,D14/MAX(T14,0.0001))))),"") -> 0 | V14: =IF(U14="","–",IF(U14>=0.9,"GREEN",IF(U14>=0.7,"YELLOW","RED"))) -> RED | W14: =IFERROR(IF(T14="","",AVERAGE(OFFSET(G14,0,MAX(0,MATCH(Dashboard!$C$2,{"Apr","May","Jun","Jul","Aug","Sep","Oct","Nov","Dec","Jan","Feb","Mar"},0)-3),1,3))),"")
A15: 11 | B15: Maternal Deaths (this month, district total) | C15: count | D15: 0 | E15: ↓ lower better | F15: M | T15: =IFERROR(INDEX(G15:R15,MATCH(Dashboard!$C$2,{"Apr","May","Jun","Jul","Aug","Sep","Oct","Nov","Dec","Jan","Feb","Mar"},0)),"") -> 0 | U15: =IFERROR(IF(T15="","",IF(LEFT(E15,1)="↑",IF(D15=0,"",MIN(1.5,T15/D15)),IF(T15=0,IF(D15=0,1,1.5),MIN(1.5,D15/MAX(T15,0.0001))))),"") -> 1 | V15: =IF(U15="","–",IF(U15>=0.9,"GREEN",IF(U15>=0.7,"YELLOW","RED"))) -> GREEN | W15: =IFERROR(IF(T15="","",AVERAGE(OFFSET(G15,0,MAX(0,MATCH(Dashboard!$C$2,{"Apr","May","Jun","Jul","Aug","Sep","Oct","Nov","Dec","Jan","Feb","Mar"},0)-3),1,3))),"")
A16: 12 | B16: Infant Deaths (this month, district total) | C16: count | D16: 2 | E16: ↓ lower better | F16: M | T16: =IFERROR(INDEX(G16:R16,MATCH(Dashboard!$C$2,{"Apr","May","Jun","Jul","Aug","Sep","Oct","Nov","Dec","Jan","Feb","Mar"},0)),"") -> 0 | U16: =IFERROR(IF(T16="","",IF(LEFT(E16,1)="↑",IF(D16=0,"",MIN(1.5,T16/D16)),IF(T16=0,IF(D16=0,1,1.5),MIN(1.5,D16/MAX(T16,0.0001))))),"") -> 1.5 | V16: =IF(U16="","–",IF(U16>=0.9,"GREEN",IF(U16>=0.7,"YELLOW","RED"))) -> GREEN | W16: =IFERROR(IF(T16="","",AVERAGE(OFFSET(G16,0,MAX(0,MATCH(Dashboard!$C$2,{"Apr","May","Jun","Jul","Aug","Sep","Oct","Nov","Dec","Jan","Feb","Mar"},0)-3),1,3))),"")
A19: Notes: | B19: Blue cells = input (you enter the number). Yellow background = current month, needs filling. Hover indicator name for owner & data source.

Sheet KRA E - Education Attendance &
A1: KRA E: Education Attendance & Outcomes
A2: Owner: DDSE (Deputy Director, School Education) | Weight in TPI: 12 | Indicators: 12
A4: # | B4: Indicator | C4: Unit | D4: Target | E4: Direction | F4: Freq | G4: Apr | H4: May | I4: Jun | J4: Jul | K4: Aug | L4: Sep | M4: Oct | N4: Nov | O4: Dec | P4: Jan | Q4: Feb | R4: Mar | T4: Current Actual | U4: Achievement % | V4: Status | W4: 3-mo Avg
A5: 1 | B5: Teacher Attendance Rate (avg across govt schools) | C5: % | D5: 85 | E5: ↑ higher better | F5: M | T5: =IFERROR(INDEX(G5:R5,MATCH(Dashboard!$C$2,{"Apr","May","Jun","Jul","Aug","Sep","Oct","Nov","Dec","Jan","Feb","Mar"},0)),"") -> 0 | U5: =IFERROR(IF(T5="","",IF(LEFT(E5,1)="↑",IF(D5=0,"",MIN(1.5,T5/D5)),IF(T5=0,IF(D5=0,1,1.5),MIN(1.5,D5/MAX(T5,0.0001))))),"") -> 0 | V5: =IF(U5="","–",IF(U5>=0.9,"GREEN",IF(U5>=0.7,"YELLOW","RED"))) -> RED | W5: =IFERROR(IF(T5="","",AVERAGE(OFFSET(G5,0,MAX(0,MATCH(Dashboard!$C$2,{"Apr","May","Jun","Jul","Aug","Sep","Oct","Nov","Dec","Jan","Feb","Mar"},0)-3),1,3))),"")
A6: 2 | B6: Student Attendance Rate (Classes 1-8) | C6: % | D6: 75 | E6: ↑ higher better | F6: M | T6: =IFERROR(INDEX(G6:R6,MATCH(Dashboard!$C$2,{"Apr","May","Jun","Jul","Aug","Sep","Oct","Nov","Dec","Jan","Feb","Mar"},0)),"") -> 0 | U6: =IFERROR(IF(T6="","",IF(LEFT(E6,1)="↑",IF(D6=0,"",MIN(1.5,T6/D6)),IF(T6=0,IF(D6=0,1,1.5),MIN(1.5,D6/MAX(T6,0.0001))))),"") -> 0 | V6: =IF(U6="","–",IF(U6>=0.9,"GREEN",IF(U6>=0.7,"YELLOW","RED"))) -> RED | W6: =IFERROR(IF(T6="","",AVERAGE(OFFSET(G6,0,MAX(0,MATCH(Dashboard!$C$2,{"Apr","May","Jun","Jul","Aug","Sep","Oct","Nov","Dec","Jan","Feb","Mar"},0)-3),1,3))),"")
A7: 3 | B7: FLN Reading Proficiency, Class 3 (NIPUN Bharat) | C7: % | D7: 50 | E7: ↑ higher better | F7: Q | T7: =IFERROR(INDEX(G7:R7,MATCH(Dashboard!$C$2,{"Apr","May","Jun","Jul","Aug","Sep","Oct","Nov","Dec","Jan","Feb","Mar"},0)),"") -> 0 | U7: =IFERROR(IF(T7="","",IF(LEFT(E7,1)="↑",IF(D7=0,"",MIN(1.5,T7/D7)),IF(T7=0,IF(D7=0,1,1.5),MIN(1.5,D7/MAX(T7,0.0001))))),"") -> 0 | V7: =IF(U7="","–",IF(U7>=0.9,"GREEN",IF(U7>=0.7,"YELLOW","RED"))) -> RED | W7: =IFERROR(IF(T7="","",AVERAGE(OFFSET(G7,0,MAX(0,MATCH(Dashboard!$C$2,{"Apr","May","Jun","Jul","Aug","Sep","Oct","Nov","Dec","Jan","Feb","Mar"},0)-3),1,3))),"")
A8: 4 | B8: FLN Numeracy Proficiency, Class 3 (NIPUN Bharat) | C8: % | D8: 50 | E8: ↑ higher better | F8: Q | T8: =IFERROR(INDEX(G8:R8,MATCH(Dashboard!$C$2,{"Apr","May","Jun","Jul","Aug","Sep","Oct","Nov","Dec","Jan","Feb","Mar"},0)),"") -> 0 | U8: =IFERROR(IF(T8="","",IF(LEFT(E8,1)="↑",IF(D8=0,"",MIN(1.5,T8/D8)),IF(T8=0,IF(D8=0,1,1.5),MIN(1.5,D8/MAX(T8,0.0001))))),"") -> 0 | V8: =IF(U8="","–",IF(U8>=0.9,"GREEN",IF(U8>=0.7,"YELLOW","RED"))) -> RED | W8: =IFERROR(IF(T8="","",AVERAGE(OFFSET(G8,0,MAX(0,MATCH(Dashboard!$C$2,{"Apr","May","Jun","Jul","Aug","Sep","Oct","Nov","Dec","Jan","Feb","Mar"},0)-3),1,3))),"")
A9: 5 | B9: Schools with Functional Toilets (separate boy/girl) | C9: % | D9: 95 | E9: ↑ higher better | F9: M | T9: =IFERROR(INDEX(G9:R9,MATCH(Dashboard!$C$2,{"Apr","May","Jun","Jul","Aug","Sep","Oct","Nov","Dec","Jan","Feb","Mar"},0)),"") -> 0 | U9: =IFERROR(IF(T9="","",IF(LEFT(E9,1)="↑",IF(D9=0,"",MIN(1.5,T9/D9)),IF(T9=0,IF(D9=0,1,1.5),MIN(1.5,D9/MAX(T9,0.0001))))),"") -> 0 | V9: =IF(U9="","–",IF(U9>=0.9,"GREEN",IF(U9>=0.7,"YELLOW","RED"))) -> RED | W9: =IFERROR(IF(T9="","",AVERAGE(OFFSET(G9,0,MAX(0,MATCH(Dashboard!$C$2,{"Apr","May","Jun","Jul","Aug","Sep","Oct","Nov","Dec","Jan","Feb","Mar"},0)-3),1,3))),"")
A10: 6 | B10: Schools with Drinking Water | C10: % | D10: 95 | E10: ↑ higher better | F10: M | T10: =IFERROR(INDEX(G10:R10,MATCH(Dashboard!$C$2,{"Apr","May","Jun","Jul","Aug","Sep","Oct","Nov","Dec","Jan","Feb","Mar"},0)),"") -> 0 | U10: =IFERROR(IF(T10="","",IF(LEFT(E10,1)="↑",IF(D10=0,"",MIN(1.5,T10/D10)),IF(T10=0,IF(D10=0,1,1.5),MIN(1.5,D10/MAX(T10,0.0001))))),"") -> 0 | V10: =IF(U10="","–",IF(U10>=0.9,"GREEN",IF(U10>=0.7,"YELLOW","RED"))) -> RED | W10: =IFERROR(IF(T10="","",AVERAGE(OFFSET(G10,0,MAX(0,MATCH(Dashboard!$C$2,{"Apr","May","Jun","Jul","Aug","Sep","Oct","Nov","Dec","Jan","Feb","Mar"},0)-3),1,3))),"")
A11: 7 | B11: Class 10 Board Pass Rate (annual; reported in March-April) | C11: % | D11: 70 | E11: ↑ higher better | F11: Q | T11: =IFERROR(INDEX(G11:R11,MATCH(Dashboard!$C$2,{"Apr","May","Jun","Jul","Aug","Sep","Oct","Nov","Dec","Jan","Feb","Mar"},0)),"") -> 0 | U11: =IFERROR(IF(T11="","",IF(LEFT(E11,1)="↑",IF(D11=0,"",MIN(1.5,T11/D11)),IF(T11=0,IF(D11=0,1,1.5),MIN(1.5,D11/MAX(T11,0.0001))))),"") -> 0 | V11: =IF(U11="","–",IF(U11>=0.9,"GREEN",IF(U11>=0.7,"YELLOW","RED"))) -> RED | W11: =IFERROR(IF(T11="","",AVERAGE(OFFSET(G11,0,MAX(0,MATCH(Dashboard!$C$2,{"Apr","May","Jun","Jul","Aug","Sep","Oct","Nov","Dec","Jan","Feb","Mar"},0)-3),1,3))),"")
A12: 8 | B12: Class 12 Board Pass Rate (annual) | C12: % | D12: 75 | E12: ↑ higher better | F12: Q | T12: =IFERROR(INDEX(G12:R12,MATCH(Dashboard!$C$2,{"Apr","May","Jun","Jul","Aug","Sep","Oct","Nov","Dec","Jan","Feb","Mar"},0)),"") -> 0 | U12: =IFERROR(IF(T12="","",IF(LEFT(E12,1)="↑",IF(D12=0,"",MIN(1.5,T12/D12)),IF(T12=0,IF(D12=0,1,1.5),MIN(1.5,D12/MAX(T12,0.0001))))),"") -> 0 | V12: =IF(U12="","–",IF(U12>=0.9,"GREEN",IF(U12>=0.7,"YELLOW","RED"))) -> RED | W12: =IFERROR(IF(T12="","",AVERAGE(OFFSET(G12,0,MAX(0,MATCH(Dashboard!$C$2,{"Apr","May","Jun","Jul","Aug","Sep","Oct","Nov","Dec","Jan","Feb","Mar"},0)-3),1,3))),"")
A13: 9 | B13: Out-of-School Children Identified & Mainstreamed | C13: count | D13: 50 | E13: ↑ higher better | F13: M | T13: =IFERROR(INDEX(G13:R13,MATCH(Dashboard!$C$2,{"Apr","May","Jun","Jul","Aug","Sep","Oct","Nov","Dec","Jan","Feb","Mar"},0)),"") -> 0 | U13: =IFERROR(IF(T13="","",IF(LEFT(E13,1)="↑",IF(D13=0,"",MIN(1.5,T13/D13)),IF(T13=0,IF(D13=0,1,1.5),MIN(1.5,D13/MAX(T13,0.0001))))),"") -> 0 | V13: =IF(U13="","–",IF(U13>=0.9,"GREEN",IF(U13>=0.7,"YELLOW","RED"))) -> RED | W13: =IFERROR(IF(T13="","",AVERAGE(OFFSET(G13,0,MAX(0,MATCH(Dashboard!$C$2,{"Apr","May","Jun","Jul","Aug","Sep","Oct","Nov","Dec","Jan","Feb","Mar"},0)-3),1,3))),"")
A14: 10 | B14: Teacher Training Days Completed (cumulative) | C14: count | D14: 100 | E14: ↑ higher better | F14: M | T14: =IFERROR(INDEX(G14:R14,MATCH(Dashboard!$C$2,{"Apr","May","Jun","Jul","Aug","Sep","Oct","Nov","Dec","Jan","Feb","Mar"},0)),"") -> 0 | U14: =IFERROR(IF(T14="","",IF(LEFT(E14,1)="↑",IF(D14=0,"",MIN(1.5,T14/D14)),IF(T14=0,IF(D14=0,1,1.5),MIN(1.5,D14/MAX(T14,0.0001))))),"") -> 0 | V14: =IF(U14="","–",IF(U14>=0.9,"GREEN",IF(U14>=0.7,"YELLOW","RED"))) -> RED | W14: =IFERROR(IF(T14="","",AVERAGE(OFFSET(G14,0,MAX(0,MATCH(Dashboard!$C$2,{"Apr","May","Jun","Jul","Aug","Sep","Oct","Nov","Dec","Jan","Feb","Mar"},0)-3),1,3))),"")
A15: 11 | B15: Schools Receiving Mid-Day Meal All Working Days | C15: % | D15: 95 | E15: ↑ higher better | F15: M | T15: =IFERROR(INDEX(G15:R15,MATCH(Dashboard!$C$2,{"Apr","May","Jun","Jul","Aug","Sep","Oct","Nov","Dec","Jan","Feb","Mar"},0)),"") -> 0 | U15: =IFERROR(IF(T15="","",IF(LEFT(E15,1)="↑",IF(D15=0,"",MIN(1.5,T15/D15)),IF(T15=0,IF(D15=0,1,1.5),MIN(1.5,D15/MAX(T15,0.0001))))),"") -> 0 | V15: =IF(U15="","–",IF(U15>=0.9,"GREEN",IF(U15>=0.7,"YELLOW","RED"))) -> RED | W15: =IFERROR(IF(T15="","",AVERAGE(OFFSET(G15,0,MAX(0,MATCH(Dashboard!$C$2,{"Apr","May","Jun","Jul","Aug","Sep","Oct","Nov","Dec","Jan","Feb","Mar"},0)-3),1,3))),"")
A16: 12 | B16: EMRS / Ashram School Hostel Occupancy | C16: % | D16: 90 | E16: ↑ higher better | F16: M | T16: =IFERROR(INDEX(G16:R16,MATCH(Dashboard!$C$2,{"Apr","May","Jun","Jul","Aug","Sep","Oct","Nov","Dec","Jan","Feb","Mar"},0)),"") -> 0 | U16: =IFERROR(IF(T16="","",IF(LEFT(E16,1)="↑",IF(D16=0,"",MIN(1.5,T16/D16)),IF(T16=0,IF(D16=0,1,1.5),MIN(1.5,D16/MAX(T16,0.0001))))),"") -> 0 | V16: =IF(U16="","–",IF(U16>=0.9,"GREEN",IF(U16>=0.7,"YELLOW","RED"))) -> RED | W16: =IFERROR(IF(T16="","",AVERAGE(OFFSET(G16,0,MAX(0,MATCH(Dashboard!$C$2,{"Apr","May","Jun","Jul","Aug","Sep","Oct","Nov","Dec","Jan","Feb","Mar"},0)-3),1,3))),"")
A19: Notes: | B19: Blue cells = input (you enter the number). Yellow background = current month, needs filling. Hover indicator name for owner & data source.

Sheet KRA A - Anganwadi & ECCE
A1: KRA A: Anganwadi & ECCE
A2: Owner: DPO (ICDS) | Weight in TPI: 8 | Indicators: 9
A4: # | B4: Indicator | C4: Unit | D4: Target | E4: Direction | F4: Freq | G4: Apr | H4: May | I4: Jun | J4: Jul | K4: Aug | L4: Sep | M4: Oct | N4: Nov | O4: Dec | P4: Jan | Q4: Feb | R4: Mar | T4: Current Actual | U4: Achievement % | V4: Status | W4: 3-mo Avg
A5: 1 | B5: AWC Functionality Score (% scoring ≥70% on 5-parameter audit) | C5: % | D5: 70 | E5: ↑ higher better | F5: M | T5: =IFERROR(INDEX(G5:R5,MATCH(Dashboard!$C$2,{"Apr","May","Jun","Jul","Aug","Sep","Oct","Nov","Dec","Jan","Feb","Mar"},0)),"") -> 0 | U5: =IFERROR(IF(T5="","",IF(LEFT(E5,1)="↑",IF(D5=0,"",MIN(1.5,T5/D5)),IF(T5=0,IF(D5=0,1,1.5),MIN(1.5,D5/MAX(T5,0.0001))))),"") -> 0 | V5: =IF(U5="","–",IF(U5>=0.9,"GREEN",IF(U5>=0.7,"YELLOW","RED"))) -> RED | W5: =IFERROR(IF(T5="","",AVERAGE(OFFSET(G5,0,MAX(0,MATCH(Dashboard!$C$2,{"Apr","May","Jun","Jul","Aug","Sep","Oct","Nov","Dec","Jan","Feb","Mar"},0)-3),1,3))),"")
A6: 2 | B6: Children 0-6 Registered in ICDS MIS | C6: % | D6: 90 | E6: ↑ higher better | F6: M | T6: =IFERROR(INDEX(G6:R6,MATCH(Dashboard!$C$2,{"Apr","May","Jun","Jul","Aug","Sep","Oct","Nov","Dec","Jan","Feb","Mar"},0)),"") -> 0 | U6: =IFERROR(IF(T6="","",IF(LEFT(E6,1)="↑",IF(D6=0,"",MIN(1.5,T6/D6)),IF(T6=0,IF(D6=0,1,1.5),MIN(1.5,D6/MAX(T6,0.0001))))),"") -> 0 | V6: =IF(U6="","–",IF(U6>=0.9,"GREEN",IF(U6>=0.7,"YELLOW","RED"))) -> RED | W6: =IFERROR(IF(T6="","",AVERAGE(OFFSET(G6,0,MAX(0,MATCH(Dashboard!$C$2,{"Apr","May","Jun","Jul","Aug","Sep","Oct","Nov","Dec","Jan","Feb","Mar"},0)-3),1,3))),"")
A7: 3 | B7: AWCs Running Daily Pre-school Activity | C7: % | D7: 80 | E7: ↑ higher better | F7: M | T7: =IFERROR(INDEX(G7:R7,MATCH(Dashboard!$C$2,{"Apr","May","Jun","Jul","Aug","Sep","Oct","Nov","Dec","Jan","Feb","Mar"},0)),"") -> 0 | U7: =IFERROR(IF(T7="","",IF(LEFT(E7,1)="↑",IF(D7=0,"",MIN(1.5,T7/D7)),IF(T7=0,IF(D7=0,1,1.5),MIN(1.5,D7/MAX(T7,0.0001))))),"") -> 0 | V7: =IF(U7="","–",IF(U7>=0.9,"GREEN",IF(U7>=0.7,"YELLOW","RED"))) -> RED | W7: =IFERROR(IF(T7="","",AVERAGE(OFFSET(G7,0,MAX(0,MATCH(Dashboard!$C$2,{"Apr","May","Jun","Jul","Aug","Sep","Oct","Nov","Dec","Jan","Feb","Mar"},0)-3),1,3))),"")
A8: 4 | B8: Saksham AWC Upgrade Status (cumulative count) | C8: count | D8: 30 | E8: ↑ higher better | F8: M | T8: =IFERROR(INDEX(G8:R8,MATCH(Dashboard!$C$2,{"Apr","May","Jun","Jul","Aug","Sep","Oct","Nov","Dec","Jan","Feb","Mar"},0)),"") -> 0 | U8: =IFERROR(IF(T8="","",IF(LEFT(E8,1)="↑",IF(D8=0,"",MIN(1.5,T8/D8)),IF(T8=0,IF(D8=0,1,1.5),MIN(1.5,D8/MAX(T8,0.0001))))),"") -> 0 | V8: =IF(U8="","–",IF(U8>=0.9,"GREEN",IF(U8>=0.7,"YELLOW","RED"))) -> RED | W8: =IFERROR(IF(T8="","",AVERAGE(OFFSET(G8,0,MAX(0,MATCH(Dashboard!$C$2,{"Apr","May","Jun","Jul","Aug","Sep","Oct","Nov","Dec","Jan","Feb","Mar"},0)-3),1,3))),"")
A9: 5 | B9: Take-Home Ration Distribution Coverage | C9: % | D9: 95 | E9: ↑ higher better | F9: M | T9: =IFERROR(INDEX(G9:R9,MATCH(Dashboard!$C$2,{"Apr","May","Jun","Jul","Aug","Sep","Oct","Nov","Dec","Jan","Feb","Mar"},0)),"") -> 0 | U9: =IFERROR(IF(T9="","",IF(LEFT(E9,1)="↑",IF(D9=0,"",MIN(1.5,T9/D9)),IF(T9=0,IF(D9=0,1,1.5),MIN(1.5,D9/MAX(T9,0.0001))))),"") -> 0 | V9: =IF(U9="","–",IF(U9>=0.9,"GREEN",IF(U9>=0.7,"YELLOW","RED"))) -> RED | W9: =IFERROR(IF(T9="","",AVERAGE(OFFSET(G9,0,MAX(0,MATCH(Dashboard!$C$2,{"Apr","May","Jun","Jul","Aug","Sep","Oct","Nov","Dec","Jan","Feb","Mar"},0)-3),1,3))),"")
A10: 6 | B10: Hot Cooked Meal Days (per AWC per month) | C10: count | D10: 20 | E10: ↑ higher better | F10: M | T10: =IFERROR(INDEX(G10:R10,MATCH(Dashboard!$C$2,{"Apr","May","Jun","Jul","Aug","Sep","Oct","Nov","Dec","Jan","Feb","Mar"},0)),"") -> 0 | U10: =IFERROR(IF(T10="","",IF(LEFT(E10,1)="↑",IF(D10=0,"",MIN(1.5,T10/D10)),IF(T10=0,IF(D10=0,1,1.5),MIN(1.5,D10/MAX(T10,0.0001))))),"") -> 0 | V10: =IF(U10="","–",IF(U10>=0.9,"GREEN",IF(U10>=0.7,"YELLOW","RED"))) -> RED | W10: =IFERROR(IF(T10="","",AVERAGE(OFFSET(G10,0,MAX(0,MATCH(Dashboard!$C$2,{"Apr","May","Jun","Jul","Aug","Sep","Oct","Nov","Dec","Jan","Feb","Mar"},0)-3),1,3))),"")
A11: 7 | B11: Severely Underweight Children (% of registered 0-6) | C11: % | D11: 5 | E11: ↓ lower better | F11: M | T11: =IFERROR(INDEX(G11:R11,MATCH(Dashboard!$C$2,{"Apr","May","Jun","Jul","Aug","Sep","Oct","Nov","Dec","Jan","Feb","Mar"},0)),"") -> 0 | U11: =IFERROR(IF(T11="","",IF(LEFT(E11,1)="↑",IF(D11=0,"",MIN(1.5,T11/D11)),IF(T11=0,IF(D11=0,1,1.5),MIN(1.5,D11/MAX(T11,0.0001))))),"") -> 1.5 | V11: =IF(U11="","–",IF(U11>=0.9,"GREEN",IF(U11>=0.7,"YELLOW","RED"))) -> GREEN | W11: =IFERROR(IF(T11="","",AVERAGE(OFFSET(G11,0,MAX(0,MATCH(Dashboard!$C$2,{"Apr","May","Jun","Jul","Aug","Sep","Oct","Nov","Dec","Jan","Feb","Mar"},0)-3),1,3))),"")
A12: 8 | B12: Stunting Rate (Class 1 entrants, annual) | C12: % | D12: 30 | E12: ↓ lower better | F12: Q | T12: =IFERROR(INDEX(G12:R12,MATCH(Dashboard!$C$2,{"Apr","May","Jun","Jul","Aug","Sep","Oct","Nov","Dec","Jan","Feb","Mar"},0)),"") -> 0 | U12: =IFERROR(IF(T12="","",IF(LEFT(E12,1)="↑",IF(D12=0,"",MIN(1.5,T12/D12)),IF(T12=0,IF(D12=0,1,1.5),MIN(1.5,D12/MAX(T12,0.0001))))),"") -> 1.5 | V12: =IF(U12="","–",IF(U12>=0.9,"GREEN",IF(U12>=0.7,"YELLOW","RED"))) -> GREEN | W12: =IFERROR(IF(T12="","",AVERAGE(OFFSET(G12,0,MAX(0,MATCH(Dashboard!$C$2,{"Apr","May","Jun","Jul","Aug","Sep","Oct","Nov","Dec","Jan","Feb","Mar"},0)-3),1,3))),"")
A13: 9 | B13: AWWs with Smartphone & POSHAN App Active | C13: % | D13: 85 | E13: ↑ higher better | F13: M | T13: =IFERROR(INDEX(G13:R13,MATCH(Dashboard!$C$2,{"Apr","May","Jun","Jul","Aug","Sep","Oct","Nov","Dec","Jan","Feb","Mar"},0)),"") -> 0 | U13: =IFERROR(IF(T13="","",IF(LEFT(E13,1)="↑",IF(D13=0,"",MIN(1.5,T13/D13)),IF(T13=0,IF(D13=0,1,1.5),MIN(1.5,D13/MAX(T13,0.0001))))),"") -> 0 | V13: =IF(U13="","–",IF(U13>=0.9,"GREEN",IF(U13>=0.7,"YELLOW","RED"))) -> RED | W13: =IFERROR(IF(T13="","",AVERAGE(OFFSET(G13,0,MAX(0,MATCH(Dashboard!$C$2,{"Apr","May","Jun","Jul","Aug","Sep","Oct","Nov","Dec","Jan","Feb","Mar"},0)-3),1,3))),"")
A16: Notes: | B16: Blue cells = input (you enter the number). Yellow background = current month, needs filling. Hover indicator name for owner & data source.

Sheet KRA D - Drug Demand-Reduction 
A1: KRA D: Drug Demand-Reduction & Youth
A2: Owner: DC + DMO + SP (joint) | Weight in TPI: 10 | Indicators: 8
A4: # | B4: Indicator | C4: Unit | D4: Target | E4: Direction | F4: Freq | G4: Apr | H4: May | I4: Jun | J4: Jul | K4: Aug | L4: Sep | M4: Oct | N4: Nov | O4: Dec | P4: Jan | Q4: Feb | R4: Mar | T4: Current Actual | U4: Achievement % | V4: Status | W4: 3-mo Avg
A5: 1 | B5: New Patients Inducted into De-addiction Programme | C5: count | D5: 30 | E5: ↑ higher better | F5: M | T5: =IFERROR(INDEX(G5:R5,MATCH(Dashboard!$C$2,{"Apr","May","Jun","Jul","Aug","Sep","Oct","Nov","Dec","Jan","Feb","Mar"},0)),"") -> 0 | U5: =IFERROR(IF(T5="","",IF(LEFT(E5,1)="↑",IF(D5=0,"",MIN(1.5,T5/D5)),IF(T5=0,IF(D5=0,1,1.5),MIN(1.5,D5/MAX(T5,0.0001))))),"") -> 0 | V5: =IF(U5="","–",IF(U5>=0.9,"GREEN",IF(U5>=0.7,"YELLOW","RED"))) -> RED | W5: =IFERROR(IF(T5="","",AVERAGE(OFFSET(G5,0,MAX(0,MATCH(Dashboard!$C$2,{"Apr","May","Jun","Jul","Aug","Sep","Oct","Nov","Dec","Jan","Feb","Mar"},0)-3),1,3))),"")
A6: 2 | B6: Recovered Users Placed in Skilling/Employment | C6: count | D6: 20 | E6: ↑ higher better | F6: M | T6: =IFERROR(INDEX(G6:R6,MATCH(Dashboard!$C$2,{"Apr","May","Jun","Jul","Aug","Sep","Oct","Nov","Dec","Jan","Feb","Mar"},0)),"") -> 0 | U6: =IFERROR(IF(T6="","",IF(LEFT(E6,1)="↑",IF(D6=0,"",MIN(1.5,T6/D6)),IF(T6=0,IF(D6=0,1,1.5),MIN(1.5,D6/MAX(T6,0.0001))))),"") -> 0 | V6: =IF(U6="","–",IF(U6>=0.9,"GREEN",IF(U6>=0.7,"YELLOW","RED"))) -> RED | W6: =IFERROR(IF(T6="","",AVERAGE(OFFSET(G6,0,MAX(0,MATCH(Dashboard!$C$2,{"Apr","May","Jun","Jul","Aug","Sep","Oct","Nov","Dec","Jan","Feb","Mar"},0)-3),1,3))),"")
A7: 3 | B7: Peer Counsellors Active (recovered users) | C7: count | D7: 15 | E7: ↑ higher better | F7: M | T7: =IFERROR(INDEX(G7:R7,MATCH(Dashboard!$C$2,{"Apr","May","Jun","Jul","Aug","Sep","Oct","Nov","Dec","Jan","Feb","Mar"},0)),"") -> 0 | U7: =IFERROR(IF(T7="","",IF(LEFT(E7,1)="↑",IF(D7=0,"",MIN(1.5,T7/D7)),IF(T7=0,IF(D7=0,1,1.5),MIN(1.5,D7/MAX(T7,0.0001))))),"") -> 0 | V7: =IF(U7="","–",IF(U7>=0.9,"GREEN",IF(U7>=0.7,"YELLOW","RED"))) -> RED | W7: =IFERROR(IF(T7="","",AVERAGE(OFFSET(G7,0,MAX(0,MATCH(Dashboard!$C$2,{"Apr","May","Jun","Jul","Aug","Sep","Oct","Nov","Dec","Jan","Feb","Mar"},0)-3),1,3))),"")
A8: 4 | B8: School-Based Drug Awareness Sessions Conducted | C8: count | D8: 30 | E8: ↑ higher better | F8: M | T8: =IFERROR(INDEX(G8:R8,MATCH(Dashboard!$C$2,{"Apr","May","Jun","Jul","Aug","Sep","Oct","Nov","Dec","Jan","Feb","Mar"},0)),"") -> 0 | U8: =IFERROR(IF(T8="","",IF(LEFT(E8,1)="↑",IF(D8=0,"",MIN(1.5,T8/D8)),IF(T8=0,IF(D8=0,1,1.5),MIN(1.5,D8/MAX(T8,0.0001))))),"") -> 0 | V8: =IF(U8="","–",IF(U8>=0.9,"GREEN",IF(U8>=0.7,"YELLOW","RED"))) -> RED | W8: =IFERROR(IF(T8="","",AVERAGE(OFFSET(G8,0,MAX(0,MATCH(Dashboard!$C$2,{"Apr","May","Jun","Jul","Aug","Sep","Oct","Nov","Dec","Jan","Feb","Mar"},0)-3),1,3))),"")
A9: 5 | B9: Sports Tournaments at Circle Level Held | C9: count | D9: 3 | E9: ↑ higher better | F9: M | T9: =IFERROR(INDEX(G9:R9,MATCH(Dashboard!$C$2,{"Apr","May","Jun","Jul","Aug","Sep","Oct","Nov","Dec","Jan","Feb","Mar"},0)),"") -> 0 | U9: =IFERROR(IF(T9="","",IF(LEFT(E9,1)="↑",IF(D9=0,"",MIN(1.5,T9/D9)),IF(T9=0,IF(D9=0,1,1.5),MIN(1.5,D9/MAX(T9,0.0001))))),"") -> 0 | V9: =IF(U9="","–",IF(U9>=0.9,"GREEN",IF(U9>=0.7,"YELLOW","RED"))) -> RED | W9: =IFERROR(IF(T9="","",AVERAGE(OFFSET(G9,0,MAX(0,MATCH(Dashboard!$C$2,{"Apr","May","Jun","Jul","Aug","Sep","Oct","Nov","Dec","Jan","Feb","Mar"},0)-3),1,3))),"")
